<?xml version="1.0"?>
<robot name="gurdy">
  <gazebo>
    <plugin name="gazebo_ros_control" filename="libgazebo_ros_control.so">
      <robotNamespace>/gurdy</robotNamespace>
    </plugin>
  </gazebo>
  <material name="gray">
    <color rgba="0.7 0.7 0.7 1"/>
  </material>
  <link name="world"/>
  <link name="base_link">
    <inertial>
      <origin xyz="0 0 0" rpy="0 0 0"/>
      <mass value="0.01"/>
      <inertia ixx="0.0001" ixy="0.0" ixz="0.0" iyy="0.0001" iyz="0.0" izz="0.0001"/>
    </inertial>
    <collision>
      <origin xyz="0 0 0" rpy="0 0 0"/>
      <geometry>
        <box size="0.01 0.01 0.01"/>
      </geometry>
    </collision>
    <!--
        <visual>
        <origin rpy="0 0 0" xyz="0 0 0"/>
            <geometry>
                <mesh filename="package://my_gurdy_description/models/gurdy/meshes/gurdy_base.dae"/>
            </geometry>
        </visual>
        -->
  </link>
  <link name="head_link">
    <inertial>
      <origin xyz="0 0 0" rpy="0 0 0"/>
      <mass value="0.01"/>
      <inertia ixx="0.0001" ixy="0.0" ixz="0.0" iyy="0.0001" iyz="0.0" izz="0.0001"/>
    </inertial>
    <collision>
      <origin xyz="0 0 0" rpy="0 0 0"/>
      <geometry>
        <cylinder radius="0.05" length="0.04"/>
      </geometry>
    </collision>
    <visual>
      <origin rpy="0 0 0" xyz="0 0 0"/>
      <geometry>
        <mesh filename="package://my_gurdy_description/models/gurdy/meshes/gurdy_head.dae"/>
      </geometry>
    </visual>
  </link>
  <link name="upperleg_M1_link">
    <inertial>
      <origin xyz="0 0 0.03" rpy="0 0 0"/>
      <mass value="0.01"/>
      <inertia ixx="0.0001" ixy="0.0" ixz="0.0" iyy="0.0001" iyz="0.0" izz="0.0001"/>
    </inertial>
    <collision>
      <origin xyz="0 0 0.03" rpy="0 0 0"/>
      <geometry>
        <cylinder radius="0.0025" length="0.06"/>
      </geometry>
    </collision>
    <visual>
      <origin xyz="0 0 0" rpy="1.579 0 0"/>
      <geometry>
        <!--
                <cylinder radius="0.0025" length="0.04"/>
                -->
        <mesh filename="package://my_gurdy_description/models/gurdy/meshes/gurdy_higherleg.dae"/>
      </geometry>
    </visual>
  </link>
  <link name="lowerleg_M1_link">
    <inertial>
      <origin xyz="0 0 0.03" rpy="0 0 0"/>
      <mass value="0.01"/>
      <inertia ixx="0.0001" ixy="0.0" ixz="0.0" iyy="0.0001" iyz="0.0" izz="0.0001"/>
    </inertial>
    <collision>
      <origin xyz="0 0 0.03" rpy="0 0 0"/>
      <geometry>
        <cylinder radius="0.0015" length="0.06"/>
      </geometry>
    </collision>
    <visual>
      <origin xyz="0 -0.015 0" rpy="1.579 0 3.14159"/>
      <geometry>
        <!--
                <cylinder radius="0.0025" length="0.04"/>
                -->
        <mesh filename="package://my_gurdy_description/models/gurdy/meshes/gurdy_lowerleg.dae"/>
      </geometry>
    </visual>
  </link>
  <link name="footM1_link">
    <inertial>
      <origin xyz="0 0 0" rpy="0 0 0"/>
      <mass value="0.01"/>
      <inertia ixx="0.0001" ixy="0.0" ixz="0.0" iyy="0.0001" iyz="0.0" izz="0.0001"/>
    </inertial>
    <collision>
      <origin xyz="0 0 0.03" rpy="0 0 0"/>
      <geometry>
        <sphere radius="0.008"/>
      </geometry>
    </collision>
    <visual>
      <origin xyz="0 0 0" rpy="0 0 0"/>
      <geometry>
        <sphere radius="0.008"/>
      </geometry>
    </visual>
  </link>
  <link name="upperleg_M2_link">
    <inertial>
      <origin xyz="0 0 0.03" rpy="0 0 0"/>
      <mass value="0.01"/>
      <inertia ixx="0.0001" ixy="0.0" ixz="0.0" iyy="0.0001" iyz="0.0" izz="0.0001"/>
    </inertial>
    <collision>
      <origin xyz="0 0 0.03" rpy="0 0 0"/>
      <geometry>
        <cylinder radius="0.0025" length="0.06"/>
      </geometry>
    </collision>
    <visual>
      <origin xyz="0 0 0" rpy="1.579 0 0"/>
      <geometry>
        <!--
                <cylinder radius="0.0025" length="0.04"/>
                -->
        <mesh filename="package://my_gurdy_description/models/gurdy/meshes/gurdy_higherleg.dae"/>
      </geometry>
    </visual>
  </link>
  <link name="lowerleg_M2_link">
    <inertial>
      <origin xyz="0 0 0.03" rpy="0 0 0"/>
      <mass value="0.01"/>
      <inertia ixx="0.0001" ixy="0.0" ixz="0.0" iyy="0.0001" iyz="0.0" izz="0.0001"/>
    </inertial>
    <collision>
      <origin xyz="0 0 0.03" rpy="0 0 0"/>
      <geometry>
        <cylinder radius="0.0015" length="0.06"/>
      </geometry>
    </collision>
    <visual>
      <origin xyz="0 -0.015 0" rpy="1.579 0 3.14159"/>
      <geometry>
        <!--
                <cylinder radius="0.0025" length="0.04"/>
                -->
        <mesh filename="package://my_gurdy_description/models/gurdy/meshes/gurdy_lowerleg.dae"/>
      </geometry>
    </visual>
  </link>
  <link name="footM2_link">
    <inertial>
      <origin xyz="0 0 0" rpy="0 0 0"/>
      <mass value="0.01"/>
      <inertia ixx="0.0001" ixy="0.0" ixz="0.0" iyy="0.0001" iyz="0.0" izz="0.0001"/>
    </inertial>
    <collision>
      <origin xyz="0 0 0.03" rpy="0 0 0"/>
      <geometry>
        <sphere radius="0.008"/>
      </geometry>
    </collision>
    <visual>
      <origin xyz="0 0 0" rpy="0 0 0"/>
      <geometry>
        <sphere radius="0.008"/>
      </geometry>
    </visual>
  </link>
  <link name="upperleg_M3_link">
    <inertial>
      <origin xyz="0 0 0.03" rpy="0 0 0"/>
      <mass value="0.01"/>
      <inertia ixx="0.0001" ixy="0.0" ixz="0.0" iyy="0.0001" iyz="0.0" izz="0.0001"/>
    </inertial>
    <collision>
      <origin xyz="0 0 0.03" rpy="0 0 0"/>
      <geometry>
        <cylinder radius="0.0025" length="0.06"/>
      </geometry>
    </collision>
    <visual>
      <origin xyz="0 0 0" rpy="1.579 0 0"/>
      <geometry>
        <!--
                <cylinder radius="0.0025" length="0.04"/>
                -->
        <mesh filename="package://my_gurdy_description/models/gurdy/meshes/gurdy_higherleg.dae"/>
      </geometry>
    </visual>
  </link>
  <link name="lowerleg_M3_link">
    <inertial>
      <origin xyz="0 0 0.03" rpy="0 0 0"/>
      <mass value="0.01"/>
      <inertia ixx="0.0001" ixy="0.0" ixz="0.0" iyy="0.0001" iyz="0.0" izz="0.0001"/>
    </inertial>
    <collision>
      <origin xyz="0 0 0.03" rpy="0 0 0"/>
      <geometry>
        <cylinder radius="0.0015" length="0.06"/>
      </geometry>
    </collision>
    <visual>
      <origin xyz="0 -0.015 0" rpy="1.579 0 3.14159"/>
      <geometry>
        <!--
                <cylinder radius="0.0025" length="0.04"/>
                -->
        <mesh filename="package://my_gurdy_description/models/gurdy/meshes/gurdy_lowerleg.dae"/>
      </geometry>
    </visual>
  </link>
  <link name="footM3_link">
    <inertial>
      <origin xyz="0 0 0" rpy="0 0 0"/>
      <mass value="0.01"/>
      <inertia ixx="0.0001" ixy="0.0" ixz="0.0" iyy="0.0001" iyz="0.0" izz="0.0001"/>
    </inertial>
    <collision>
      <origin xyz="0 0 0.03" rpy="0 0 0"/>
      <geometry>
        <sphere radius="0.008"/>
      </geometry>
    </collision>
    <visual>
      <origin xyz="0 0 0" rpy="0 0 0"/>
      <geometry>
        <sphere radius="0.008"/>
      </geometry>
    </visual>
  </link>
  <!-- Dummy Link -->
  <joint name="world_joint" type="fixed">
    <parent link="world"/>
    <child link="base_link"/>
    <origin xyz="0 0 0" rpy="0 0 0"/>
    <axis xyz="0 0 1"/>
  </joint>
  <joint name="head_joint" type="fixed">
    <parent link="base_link"/>
    <child link="head_link"/>
    <origin xyz="0 0 0" rpy="0 0 0"/>
    <axis xyz="0 0 1"/>
  </joint>
  <joint name="head_upperlegM1_joint" type="revolute">
    <parent link="head_link"/>
    <child link="upperleg_M1_link"/>
    <!-- It is not clear the directon of the rotation This nodes not
             correspond with the  blueprint given in the quiz statement-->
    <origin xyz="-0.02165 -0.0125 0.005" rpy="3.14159 0 -2.61799"/>
    <limit lower="-0.2" upper="0.2" effort="1" velocity="0.005"/>
    <axis xyz="0 1 0"/>
  </joint>
  <joint name="upperlegM1_lowerlegM1_joint" type="revolute">
    <parent link="upperleg_M1_link"/>
    <child link="lowerleg_M1_link"/>
    <origin xyz="0 0 0.06" rpy="0 0 0"/>
    <limit lower="-0.2" upper="0.2" effort="1" velocity="0.005"/>
    <axis xyz="0 1 0"/>
  </joint>
  <joint name="basefoot_peg_M1_basefoot_M1_joint_joint" type="fixed">
    <parent link="lowerleg_M1_link"/>
    <child link="footM1_link"/>
    <origin xyz="0 0 0.06" rpy="0 0 0"/>
  </joint>
  <joint name="head_upperlegM2_joint" type="revolute">
    <parent link="head_link"/>
    <child link="upperleg_M2_link"/>
    <!-- It is not clear the directon of the rotation This nodes not
             correspond with the  blueprint given in the quiz statement-->
    <origin xyz="0.02165 -0.0125 0.005" rpy="3.14159 0 -0.523599"/>
    <limit lower="-0.2" upper="0.2" effort="1" velocity="0.005"/>
    <axis xyz="0 1 0"/>
  </joint>
  <joint name="upperlegM2_lowerlegM2_joint" type="revolute">
    <parent link="upperleg_M2_link"/>
    <child link="lowerleg_M2_link"/>
    <origin xyz="0 0 0.06" rpy="0 0 0"/>
    <limit lower="-0.2" upper="0.2" effort="1" velocity="0.005"/>
    <axis xyz="0 1 0"/>
  </joint>
  <joint name="basefoot_peg_M2_basefoot_M2_joint_joint" type="fixed">
    <parent link="lowerleg_M2_link"/>
    <child link="footM2_link"/>
    <origin xyz="0 0 0.06" rpy="0 0 0"/>
  </joint>
  <joint name="head_upperlegM3_joint" type="revolute">
    <parent link="head_link"/>
    <child link="upperleg_M3_link"/>
    <!-- It is not clear the directon of the rotation This nodes not
             correspond with the  blueprint given in the quiz statement-->
    <origin xyz="0.0 0.0254 0.005" rpy="3.14159 0 1.579"/>
    <limit lower="-0.2" upper="0.2" effort="1" velocity="0.005"/>
    <axis xyz="0 1 0"/>
  </joint>
  <joint name="upperlegM3_lowerlegM3_joint" type="revolute">
    <parent link="upperleg_M3_link"/>
    <child link="lowerleg_M3_link"/>
    <origin xyz="0 0 0.06" rpy="0 0 0"/>
    <limit lower="-0.2" upper="0.2" effort="1" velocity="0.005"/>
    <axis xyz="0 1 0"/>
  </joint>
  <joint name="basefoot_peg_M3_basefoot_M3_joint_joint" type="fixed">
    <parent link="lowerleg_M3_link"/>
    <child link="footM3_link"/>
    <origin xyz="0 0 0.06" rpy="0 0 0"/>
  </joint>
  <gazebo reference="base_link">
    <kp>1000.0</kp>
    <kd>10.0</kd>
    <mu1>10.0</mu1>
    <mu2>10.0</mu2>
  </gazebo>
  <gazebo reference="head_link">
    <kp>1000.0</kp>
    <kd>10.0</kd>
    <mu1>10.0</mu1>
    <mu2>10.0</mu2>
  </gazebo>
  <gazebo reference="upperleg_M1_link">
    <kp>1000.0</kp>
    <kd>10.0</kd>
    <mu1>10.0</mu1>
    <mu2>10.0</mu2>
  </gazebo>
  <gazebo reference="lowerleg_M1_link">
    <kp>1000.0</kp>
    <kd>10.0</kd>
    <mu1>10.0</mu1>
    <mu2>10.0</mu2>
  </gazebo>
  <gazebo reference="footM1_link">
    <kp>1000.0</kp>
    <kd>10.0</kd>
    <mu1>10.0</mu1>
    <mu2>10.0</mu2>
  </gazebo>
  <gazebo reference="upperleg_M2_link">
    <kp>1000.0</kp>
    <kd>10.0</kd>
    <mu1>10.0</mu1>
    <mu2>10.0</mu2>
  </gazebo>
  <gazebo reference="lowerleg_M2_link">
    <kp>1000.0</kp>
    <kd>10.0</kd>
    <mu1>10.0</mu1>
    <mu2>10.0</mu2>
  </gazebo>
  <gazebo reference="footM2_link">
    <kp>1000.0</kp>
    <kd>10.0</kd>
    <mu1>10.0</mu1>
    <mu2>10.0</mu2>
  </gazebo>
  <gazebo reference="upperleg_M3_link">
    <kp>1000.0</kp>
    <kd>10.0</kd>
    <mu1>10.0</mu1>
    <mu2>10.0</mu2>
  </gazebo>
  <gazebo reference="lowerleg_M3_link">
    <kp>1000.0</kp>
    <kd>10.0</kd>
    <mu1>10.0</mu1>
    <mu2>10.0</mu2>
  </gazebo>
  <gazebo reference="footM3_link">
    <kp>1000.0</kp>
    <kd>10.0</kd>
    <mu1>10.0</mu1>
    <mu2>10.0</mu2>
  </gazebo>
  <transmission name="tran1_M1">
    <type>transmission_interface/SimpleTransmission</type>
    <joint name="head_upperlegM1_joint">
      <hardwareInterface>EffortJointInterface</hardwareInterface>
    </joint>
    <actuator name="motor1_M1">
      <hardwareInterface>EffortJointInterface</hardwareInterface>
      <mechanicalReduction>1</mechanicalReduction>
    </actuator>
  </transmission>
  <transmission name="tran2_M1">
    <type>transmission_interface/SimpleTransmission</type>
    <joint name="upperlegM1_lowerlegM1_joint">
      <hardwareInterface>EffortJointInterface</hardwareInterface>
    </joint>
    <actuator name="motor2_M1">
      <hardwareInterface>EffortJointInterface</hardwareInterface>
      <mechanicalReduction>1</mechanicalReduction>
    </actuator>
  </transmission>
  <transmission name="tran1_M2">
    <type>transmission_interface/SimpleTransmission</type>
    <joint name="head_upperlegM2_joint">
      <hardwareInterface>EffortJointInterface</hardwareInterface>
    </joint>
    <actuator name="motor1_M2">
      <hardwareInterface>EffortJointInterface</hardwareInterface>
      <mechanicalReduction>1</mechanicalReduction>
    </actuator>
  </transmission>
  <transmission name="tran2_M2">
    <type>transmission_interface/SimpleTransmission</type>
    <joint name="upperlegM2_lowerlegM2_joint">
      <hardwareInterface>EffortJointInterface</hardwareInterface>
    </joint>
    <actuator name="motor2_M2">
      <hardwareInterface>EffortJointInterface</hardwareInterface>
      <mechanicalReduction>1</mechanicalReduction>
    </actuator>
  </transmission>
  <transmission name="tran1_M3">
    <type>transmission_interface/SimpleTransmission</type>
    <joint name="head_upperlegM3_joint">
      <hardwareInterface>EffortJointInterface</hardwareInterface>
    </joint>
    <actuator name="motor1_M3">
      <hardwareInterface>EffortJointInterface</hardwareInterface>
      <mechanicalReduction>1</mechanicalReduction>
    </actuator>
  </transmission>
  <transmission name="tran2_M3">
    <type>transmission_interface/SimpleTransmission</type>
    <joint name="upperlegM3_lowerlegM3_joint">
      <hardwareInterface>EffortJointInterface</hardwareInterface>
    </joint>
    <actuator name="motor2_M3">
      <hardwareInterface>EffortJointInterface</hardwareInterface>
      <mechanicalReduction>1</mechanicalReduction>
    </actuator>
  </transmission>
  <gazebo>
    <plugin name="gazebo_ros_imu_controller" filename="libgazebo_ros_imu.so">
      <robotNamespace>/gurdy</robotNamespace>
      <topicName>imu/data</topicName>
      <serviceName>imu/service</serviceName>
      <bodyName>base_link</bodyName>
      <gaussianNoise>0</gaussianNoise>
      <rpyOffsets>0 0 0</rpyOffsets>
      <updateRate>10.0</updateRate>
      <alwaysOn>true</alwaysOn>
      <gaussianNoise>0</gaussianNoise>
    </plugin>
  </gazebo>
</robot>
